Workbook

Sheet Parámetros
A1: Parámetros de Costeo — Proyecto GMG Repuestos (Bot Gmgrepuestos)
A2: Equipo: Vicente Ignacio Santibáñez Zúñiga (Product Owner) y Martin Felipe Núñez Torres (Scrum Master) — ambos integran el Equipo de Desarrollo
A4: Costo por Hora según Rol (sueldo promedio de mercado)
A5: Sigla | B5: Rol | C5: Integrante(s) | D5: Sueldo Mensual Promedio (CLP) | E5: Horas / Mes | F5: Costo por Hora (CLP)
A6: PO | B6: Product Owner | C6: Vicente Santibáñez | D6: 1369009 | E6: 180 | F6: =D6/E6 -> 7605.6056
A7: SM | B7: Scrum Master | C7: Martin Núñez | D7: 1962255 | E7: 180 | F7: =D7/E7 -> 10901.417
A8: ED | B8: Equipo de Desarrollo (Programador Full Stack) | C8: Vicente Santibáñez y Martin Núñez | D8: 987539 | E8: 180 | F8: =D8/E8 -> 5486.3278
A11: Supuestos de Dedicación en Ceremonias Scrum (Product Owner y Scrum Master)
A12: El burndown real solo registra horas de construcción del Equipo de Desarrollo. Las horas de PO y SM se estiman aplicando los topes de tiempo del Scrum Guide (Planning ≤8h, Review ≤4h, Retro ≤3h para un sprint de referencia de 20 días hábiles) escalados según la duración real de cada sprint, más Daily Scrum, refinamiento de backlog y gestión de impedimentos.
A13: Parámetro | B13: Valor | C13: Reparto PO / SM
A14: Sprint de referencia (días hábiles, Scrum Guide = 1 mes) | B14: 20
A15: Sprint Planning (h, tope Scrum Guide ≤8h/mes) | B15: 8 | C15: 50% / 50%
A16: Sprint Review (h, tope Scrum Guide ≤4h/mes) | B16: 4 | C16: 50% / 50%
A17: Retrospectiva (h, tope Scrum Guide ≤3h/mes) | B17: 3 | C17: 33% / 67%
A18: Daily Scrum (h por día hábil, facilitado por SM) | B18: 0.25 | C18: 0% / 100%
A19: Refinamiento de Backlog (h por día hábil, PO) | B19: 0.15 | C19: 100% / 0%
A20: Gestión de impedimentos (h por día hábil, SM) | B20: 0.15 | C20: 0% / 100%
A22: Celdas en amarillo/azul = supuestos editables. Cambiarlas recalcula el costeo en las hojas siguientes.

Sheet Costeo por Sprint
A1: Planilla de Costos — Proyecto GMG Repuestos (por Sprint)
A2: Horas de Equipo de Desarrollo = burndown real. Horas de Product Owner y Scrum Master = estimadas según supuestos de la hoja 'Parámetros'.
A3: Sprint | B3: Fechas | C3: Días Hábiles | D3: Horas Equipo Desarrollo | E3: Costo Equipo Desarrollo | F3: Horas Product Owner | G3: Costo Product Owner | H3: Horas Scrum Master | I3: Costo Scrum Master | J3: Costo Total Sprint
A4: Sprint 1: Levantamiento de requerimientos y catálogo piloto | B4: 01/09/2026 al 14/09/2026 | C4: 10 | D4: ='EDT - Historias de Usuario'!D9 -> 68 | E4: =D4*Parámetros!$F$8 -> 373070.29 | F4: =((Parámetros!$B$15*0.5)+(Parámetros!$B$16*0.5)+(Parámetros!$B$17*(1/3)))*(C4/Parámetros!$B$14)+(Parámetros!$B$19*C4) -> 5 | G4: =F4*Parámetros!$F$6 -> 38028.028 | H4: =(Parámetros!$B$18*C4)+(((Parámetros!$B$15*0.5)+(Parámetros!$B$16*0.5)+(Parámetros!$B$17*(2/3)))*(C4/Parámetros!$B$14))+(Parámetros!$B$20*C4) -> 8 | I4: =H4*Parámetros!$F$7 -> 87211.333 | J4: =E4+G4+I4 -> 498309.65
A5: Sprint 2: Diseño de arquitectura del sistema e integraciones | B5: 07/09/2026 al 18/09/2026 | C5: 9 | D5: ='EDT - Historias de Usuario'!D16 -> 63 | E5: =D5*Parámetros!$F$8 -> 345638.65 | F5: =((Parámetros!$B$15*0.5)+(Parámetros!$B$16*0.5)+(Parámetros!$B$17*(1/3)))*(C5/Parámetros!$B$14)+(Parámetros!$B$19*C5) -> 4.5 | G5: =F5*Parámetros!$F$6 -> 34225.225 | H5: =(Parámetros!$B$18*C5)+(((Parámetros!$B$15*0.5)+(Parámetros!$B$16*0.5)+(Parámetros!$B$17*(2/3)))*(C5/Parámetros!$B$14))+(Parámetros!$B$20*C5) -> 7.2 | I5: =H5*Parámetros!$F$7 -> 78490.2 | J5: =E5+G5+I5 -> 458354.08
A6: Sprint 3: Modelado y diseño de la base de datos relacional | B6: 14/09/2026 al 25/09/2026 | C6: 9 | D6: ='EDT - Historias de Usuario'!D22 -> 57 | E6: =D6*Parámetros!$F$8 -> 312720.68 | F6: =((Parámetros!$B$15*0.5)+(Parámetros!$B$16*0.5)+(Parámetros!$B$17*(1/3)))*(C6/Parámetros!$B$14)+(Parámetros!$B$19*C6) -> 4.5 | G6: =F6*Parámetros!$F$6 -> 34225.225 | H6: =(Parámetros!$B$18*C6)+(((Parámetros!$B$15*0.5)+(Parámetros!$B$16*0.5)+(Parámetros!$B$17*(2/3)))*(C6/Parámetros!$B$14))+(Parámetros!$B$20*C6) -> 7.2 | I6: =H6*Parámetros!$F$7 -> 78490.2 | J6: =E6+G6+I6 -> 425436.11
A7: Sprint 4: Diseño del flujo de conversaciones y UX/UI del bot | B7: 21/09/2026 al 02/10/2026 | C7: 10 | D7: ='EDT - Historias de Usuario'!D32 -> 82 | E7: =D7*Parámetros!$F$8 -> 449878.88 | F7: =((Parámetros!$B$15*0.5)+(Parámetros!$B$16*0.5)+(Parámetros!$B$17*(1/3)))*(C7/Parámetros!$B$14)+(Parámetros!$B$19*C7) -> 5 | G7: =F7*Parámetros!$F$6 -> 38028.028 | H7: =(Parámetros!$B$18*C7)+(((Parámetros!$B$15*0.5)+(Parámetros!$B$16*0.5)+(Parámetros!$B$17*(2/3)))*(C7/Parámetros!$B$14))+(Parámetros!$B$20*C7) -> 8 | I7: =H7*Parámetros!$F$7 -> 87211.333 | J7: =E7+G7+I7 -> 575118.24
A8: Sprint 5: Implementación de BBDD y desarrollo backend API | B8: 28/09/2026 al 23/10/2026 | C8: 19 | D8: ='EDT - Historias de Usuario'!D58 -> 200 | E8: =D8*Parámetros!$F$8 -> 1097265.6 | F8: =((Parámetros!$B$15*0.5)+(Parámetros!$B$16*0.5)+(Parámetros!$B$17*(1/3)))*(C8/Parámetros!$B$14)+(Parámetros!$B$19*C8) -> 9.5 | G8: =F8*Parámetros!$F$6 -> 72253.253 | H8: =(Parámetros!$B$18*C8)+(((Parámetros!$B$15*0.5)+(Parámetros!$B$16*0.5)+(Parámetros!$B$17*(2/3)))*(C8/Parámetros!$B$14))+(Parámetros!$B$20*C8) -> 15.2 | I8: =H8*Parámetros!$F$7 -> 165701.53 | J8: =E8+G8+I8 -> 1335220.3
A9: Sprint 6: Integración de IA y visión computacional | B9: 19/10/2026 al 13/11/2026 | C9: 20 | D9: ='EDT - Historias de Usuario'!D67 -> 122 | E9: =D9*Parámetros!$F$8 -> 669331.99 | F9: =((Parámetros!$B$15*0.5)+(Parámetros!$B$16*0.5)+(Parámetros!$B$17*(1/3)))*(C9/Parámetros!$B$14)+(Parámetros!$B$19*C9) -> 10 | G9: =F9*Parámetros!$F$6 -> 76056.056 | H9: =(Parámetros!$B$18*C9)+(((Parámetros!$B$15*0.5)+(Parámetros!$B$16*0.5)+(Parámetros!$B$17*(2/3)))*(C9/Parámetros!$B$14))+(Parámetros!$B$20*C9) -> 16 | I9: =H9*Parámetros!$F$7 -> 174422.67 | J9: =E9+G9+I9 -> 919810.71
A10: Sprint 7: Desarrollo de módulo de conversaciones y recomendación | B10: 02/11/2026 al 27/11/2026 | C10: 20 | D10: ='EDT - Historias de Usuario'!D86 -> 118 | E10: =D10*Parámetros!$F$8 -> 647386.68 | F10: =((Parámetros!$B$15*0.5)+(Parámetros!$B$16*0.5)+(Parámetros!$B$17*(1/3)))*(C10/Parámetros!$B$14)+(Parámetros!$B$19*C10) -> 10 | G10: =F10*Parámetros!$F$6 -> 76056.056 | H10: =(Parámetros!$B$18*C10)+(((Parámetros!$B$15*0.5)+(Parámetros!$B$16*0.5)+(Parámetros!$B$17*(2/3)))*(C10/Parámetros!$B$14))+(Parámetros!$B$20*C10) -> 16 | I10: =H10*Parámetros!$F$7 -> 174422.67 | J10: =E10+G10+I10 -> 897865.4
A11: Sprint 8: Integración integral (Frontend + Backend + IA) | B11: 23/11/2026 al 11/12/2026 | C11: 14 | D11: ='EDT - Historias de Usuario'!D108 -> 134 | E11: =D11*Parámetros!$F$8 -> 735167.92 | F11: =((Parámetros!$B$15*0.5)+(Parámetros!$B$16*0.5)+(Parámetros!$B$17*(1/3)))*(C11/Parámetros!$B$14)+(Parámetros!$B$19*C11) -> 7 | G11: =F11*Parámetros!$F$6 -> 53239.239 | H11: =(Parámetros!$B$18*C11)+(((Parámetros!$B$15*0.5)+(Parámetros!$B$16*0.5)+(Parámetros!$B$17*(2/3)))*(C11/Parámetros!$B$14))+(Parámetros!$B$20*C11) -> 11.2 | I11: =H11*Parámetros!$F$7 -> 122095.87 | J11: =E11+G11+I11 -> 910503.03
A12: Sprint 9: Pruebas de calidad y validación de catálogo | B12: 07/12/2026 al 18/12/2026 | C12: 9 | D12: ='EDT - Historias de Usuario'!D120 -> 81 | E12: =D12*Parámetros!$F$8 -> 444392.55 | F12: =((Parámetros!$B$15*0.5)+(Parámetros!$B$16*0.5)+(Parámetros!$B$17*(1/3)))*(C12/Parámetros!$B$14)+(Parámetros!$B$19*C12) -> 4.5 | G12: =F12*Parámetros!$F$6 -> 34225.225 | H12: =(Parámetros!$B$18*C12)+(((Parámetros!$B$15*0.5)+(Parámetros!$B$16*0.5)+(Parámetros!$B$17*(2/3)))*(C12/Parámetros!$B$14))+(Parámetros!$B$20*C12) -> 7.2 | I12: =H12*Parámetros!$F$7 -> 78490.2 | J12: =E12+G12+I12 -> 557107.97
A13: TOTAL PROYECTO | B13: 01/09/2026 – 18/12/2026 | C13: =SUM(C4:C12) -> 120 | D13: =SUM(D4:D12) -> 925 | E13: =SUM(E4:E12) -> 5074853.2 | F13: =SUM(F4:F12) -> 60 | G13: =SUM(G4:G12) -> 456336.33 | H13: =SUM(H4:H12) -> 96 | I13: =SUM(I4:I12) -> 1046536 | J13: =SUM(J4:J12) -> 6577725.5
A15: Resumen del Proyecto
A16: Historias de Usuario totales | B16: 99
A17: Horas Equipo de Desarrollo (burndown real) | B17: =D13 -> 925
A18: Horas Product Owner (estimadas, ceremonias) | B18: =F13 -> 60
A19: Horas Scrum Master (estimadas, ceremonias) | B19: =H13 -> 96
A20: Costo Equipo de Desarrollo | B20: =E13 -> 5074853.2
A21: Costo Product Owner | B21: =G13 -> 456336.33
A22: Costo Scrum Master | B22: =I13 -> 1046536
A23: COSTO TOTAL DEL PROYECTO | B23: =J13 -> 6577725.5

Sheet EDT - Historias de Usuario
A1: EDT — Historias de Usuario y Costo del Equipo de Desarrollo (según burndown real por Sprint)
A2: Fuente: plantilla_burndown_GMG_Repuestos_1.xlsx (horas estimadas por historia, columna 'horas estimadas' de cada hoja Sprint)
A3: Sprint | B3: Código | C3: Historia de Usuario | D3: Horas Estimadas (Equipo de Desarrollo) | E3: Costo Equipo de Desarrollo (CLP)
A4: Sprint 1: Levantamiento de requerimientos y catálogo piloto (01/09/2026 al 14/09/2026)
A5: Sprint 1 | B5: E2-H4 | C5: Ver compatibilidad por modelo y año | D5: 23 | E5: =D5*Parámetros!$F$8 -> 126185.54
A6: Sprint 1 | B6: E2-H2 | C6: Filtrar el catálogo por modelo Suzuki | D6: 14 | E6: =D6*Parámetros!$F$8 -> 76808.589
A7: Sprint 1 | B7: E9-H1 | C7: Páginas informativas y legales en el pie | D7: 23 | E7: =D7*Parámetros!$F$8 -> 126185.54
A8: Sprint 1 | B8: E10-H14 | C8: Fechas, horarios e idioma de Chile | D8: 8 | E8: =D8*Parámetros!$F$8 -> 43890.622
C9: Subtotal Sprint 1 | D9: =SUM(D5:D8) -> 68 | E9: =SUM(E5:E8) -> 373070.29
A10: Sprint 2: Diseño de arquitectura del sistema e integraciones (07/09/2026 al 18/09/2026)
A11: Sprint 2 | B11: E10-H11 | C11: Hosting, ambientes separados y control de versiones | D11: 19 | E11: =D11*Parámetros!$F$8 -> 104240.23
A12: Sprint 2 | B12: E8-H8 | C12: Renderizado del catálogo en el servidor | D12: 14 | E12: =D12*Parámetros!$F$8 -> 76808.589
A13: Sprint 2 | B13: E10-H4 | C13: Proteger configuración, credenciales y BD | D13: 9 | E13: =D13*Parámetros!$F$8 -> 49376.95
A14: Sprint 2 | B14: E10-H1 | C14: Conexión cifrada (HTTPS) | D14: 7 | E14: =D14*Parámetros!$F$8 -> 38404.294
A15: Sprint 2 | B15: E10-H13 | C15: Código ordenado y documentado | D15: 14 | E15: =D15*Parámetros!$F$8 -> 76808.589
C16: Subtotal Sprint 2 | D16: =SUM(D11:D15) -> 63 | E16: =SUM(E11:E15) -> 345638.65
A17: Sprint 3: Modelado y diseño de la base de datos relacional (14/09/2026 al 25/09/2026)
A18: Sprint 3 | B18: E10-H12 | C18: Agregar modelos y categorías sin cambiar código | D18: 12 | E18: =D18*Parámetros!$F$8 -> 65835.933
A19: Sprint 3 | B19: E3-H7 | C19: Registrar el pedido con número único | D19: 15 | E19: =D19*Parámetros!$F$8 -> 82294.917
A20: Sprint 3 | B20: E4-H4 | C20: Registrar cada intento de pago | D20: 15 | E20: =D20*Parámetros!$F$8 -> 82294.917
A21: Sprint 3 | B21: E10-H7 | C21: Auditoría de cambios en el panel | D21: 15 | E21: =D21*Parámetros!$F$8 -> 82294.917
C22: Subtotal Sprint 3 | D22: =SUM(D18:D21) -> 57 | E22: =SUM(E18:E21) -> 312720.68
A23: Sprint 4: Diseño del flujo de conversaciones y UX/UI del bot (21/09/2026 al 02/10/2026)
A24: Sprint 4 | B24: E9-H4 | C24: Identidad visual consistente | D24: 10 | E24: =D24*Parámetros!$F$8 -> 54863.278
A25: Sprint 4 | B25: E5-H1 | C25: Chat flotante en todas las páginas | D25: 13 | E25: =D25*Parámetros!$F$8 -> 71322.261
A26: Sprint 4 | B26: E5-H4 | C26: Preguntar modelo y año del vehículo | D26: 10 | E26: =D26*Parámetros!$F$8 -> 54863.278
A27: Sprint 4 | B27: E5-H9 | C27: Responder horarios, despacho, pagos y garantía | D27: 10 | E27: =D27*Parámetros!$F$8 -> 54863.278
A28: Sprint 4 | B28: E9-H2 | C28: Sitio adaptable a celular, tablet y PC | D28: 16 | E28: =D28*Parámetros!$F$8 -> 87781.244
A29: Sprint 4 | B29: E9-H3 | C29: Chat adaptado a pantallas móviles | D29: 8 | E29: =D29*Parámetros!$F$8 -> 43890.622
A30: Sprint 4 | B30: E9-H6 | C30: Compra en pocos pasos con errores claros | D30: 8 | E30: =D30*Parámetros!$F$8 -> 43890.622
A31: Sprint 4 | B31: E9-H7 | C31: Mensajes de carga, éxito y error | D31: 7 | E31: =D31*Parámetros!$F$8 -> 38404.294
C32: Subtotal Sprint 4 | D32: =SUM(D24:D31) -> 82 | E32: =SUM(E24:E31) -> 449878.88
A33: Sprint 5: Implementación de BBDD y desarrollo backend API (28/09/2026 al 23/10/2026)
A34: Sprint 5 | B34: E1-H1 | C34: Iniciar sesión en el panel de administración | D34: 13 | E34: =D34*Parámetros!$F$8 -> 71322.261
A35: Sprint 5 | B35: E1-H2 | C35: Cerrar sesión desde cualquier vista del panel | D35: 3 | E35: =D35*Parámetros!$F$8 -> 16458.983
A36: Sprint 5 | B36: E1-H3 | C36: Exigir sesión activa en todas las páginas del panel | D36: 4 | E36: =D36*Parámetros!$F$8 -> 21945.311
A37: Sprint 5 | B37: E1-H5 | C37: Restablecer contraseña por correo | D37: 9 | E37: =D37*Parámetros!$F$8 -> 49376.95
A38: Sprint 5 | B38: E6-H1 | C38: Crear, editar, desactivar y eliminar productos | D38: 13 | E38: =D38*Parámetros!$F$8 -> 71322.261
A39: Sprint 5 | B39: E6-H2 | C39: Subir imágenes de productos | D39: 6 | E39: =D39*Parámetros!$F$8 -> 32917.967
A40: Sprint 5 | B40: E6-H3 | C40: Editar stock y precio desde el listado | D40: 5 | E40: =D40*Parámetros!$F$8 -> 27431.639
...
